[2022-12-13 22:59:48,159] {processor.py:153} INFO - Started process (PID=34991) to work on /home/igor/Documents/airflowalura/dags/dados_climaticos.py
[2022-12-13 22:59:48,184] {processor.py:641} INFO - Processing file /home/igor/Documents/airflowalura/dags/dados_climaticos.py for tasks to queue
[2022-12-13 22:59:48,195] {logging_mixin.py:115} INFO - [2022-12-13 22:59:48,186] {dagbag.py:507} INFO - Filling up the DagBag from /home/igor/Documents/airflowalura/dags/dados_climaticos.py
[2022-12-13 23:00:03,134] {logging_mixin.py:115} INFO - [2022-12-13 23:00:03,065] {dagbag.py:320} ERROR - Failed to import: /home/igor/Documents/airflowalura/dags/dados_climaticos.py
Traceback (most recent call last):
  File "/home/igor/Documents/airflowalura/venv/lib/python3.9/site-packages/airflow/models/dagbag.py", line 317, in parse
    loader.exec_module(new_module)
  File "<frozen importlib._bootstrap_external>", line 850, in exec_module
  File "<frozen importlib._bootstrap>", line 228, in _call_with_frames_removed
  File "/home/igor/Documents/airflowalura/dags/dados_climaticos.py", line 40, in <module>
    task_2 = PythonOperator(
  File "/home/igor/Documents/airflowalura/venv/lib/python3.9/site-packages/airflow/models/baseoperator.py", line 390, in apply_defaults
    result = func(self, **kwargs, default_args=default_args)
  File "/home/igor/Documents/airflowalura/venv/lib/python3.9/site-packages/airflow/operators/python.py", line 156, in __init__
    super().__init__(**kwargs)
  File "/home/igor/Documents/airflowalura/venv/lib/python3.9/site-packages/airflow/models/baseoperator.py", line 390, in apply_defaults
    result = func(self, **kwargs, default_args=default_args)
  File "/home/igor/Documents/airflowalura/venv/lib/python3.9/site-packages/airflow/models/baseoperator.py", line 754, in __init__
    validate_key(task_id)
  File "/home/igor/Documents/airflowalura/venv/lib/python3.9/site-packages/airflow/utils/helpers.py", line 63, in validate_key
    raise AirflowException(
airflow.exceptions.AirflowException: The key 'extrai dados' has to be made of alphanumeric characters, dashes, dots and underscores exclusively
[2022-12-13 23:00:03,148] {processor.py:653} WARNING - No viable dags retrieved from /home/igor/Documents/airflowalura/dags/dados_climaticos.py
[2022-12-13 23:00:03,290] {processor.py:161} INFO - Processing /home/igor/Documents/airflowalura/dags/dados_climaticos.py took 15.233 seconds
[2022-12-13 23:01:25,483] {processor.py:153} INFO - Started process (PID=35403) to work on /home/igor/Documents/airflowalura/dags/dados_climaticos.py
[2022-12-13 23:01:25,501] {processor.py:641} INFO - Processing file /home/igor/Documents/airflowalura/dags/dados_climaticos.py for tasks to queue
[2022-12-13 23:01:25,503] {logging_mixin.py:115} INFO - [2022-12-13 23:01:25,503] {dagbag.py:507} INFO - Filling up the DagBag from /home/igor/Documents/airflowalura/dags/dados_climaticos.py
[2022-12-13 23:01:32,677] {logging_mixin.py:115} INFO - [2022-12-13 23:01:32,665] {dagbag.py:320} ERROR - Failed to import: /home/igor/Documents/airflowalura/dags/dados_climaticos.py
Traceback (most recent call last):
  File "/home/igor/Documents/airflowalura/venv/lib/python3.9/site-packages/airflow/models/dagbag.py", line 317, in parse
    loader.exec_module(new_module)
  File "<frozen importlib._bootstrap_external>", line 850, in exec_module
  File "<frozen importlib._bootstrap>", line 228, in _call_with_frames_removed
  File "/home/igor/Documents/airflowalura/dags/dados_climaticos.py", line 40, in <module>
    task_2 = PythonOperator(
  File "/home/igor/Documents/airflowalura/venv/lib/python3.9/site-packages/airflow/models/baseoperator.py", line 390, in apply_defaults
    result = func(self, **kwargs, default_args=default_args)
  File "/home/igor/Documents/airflowalura/venv/lib/python3.9/site-packages/airflow/operators/python.py", line 156, in __init__
    super().__init__(**kwargs)
  File "/home/igor/Documents/airflowalura/venv/lib/python3.9/site-packages/airflow/models/baseoperator.py", line 390, in apply_defaults
    result = func(self, **kwargs, default_args=default_args)
  File "/home/igor/Documents/airflowalura/venv/lib/python3.9/site-packages/airflow/models/baseoperator.py", line 754, in __init__
    validate_key(task_id)
  File "/home/igor/Documents/airflowalura/venv/lib/python3.9/site-packages/airflow/utils/helpers.py", line 63, in validate_key
    raise AirflowException(
airflow.exceptions.AirflowException: The key 'extrai dados' has to be made of alphanumeric characters, dashes, dots and underscores exclusively
[2022-12-13 23:01:32,678] {processor.py:653} WARNING - No viable dags retrieved from /home/igor/Documents/airflowalura/dags/dados_climaticos.py
[2022-12-13 23:01:32,779] {processor.py:161} INFO - Processing /home/igor/Documents/airflowalura/dags/dados_climaticos.py took 7.353 seconds
[2022-12-13 23:02:26,402] {processor.py:153} INFO - Started process (PID=35633) to work on /home/igor/Documents/airflowalura/dags/dados_climaticos.py
[2022-12-13 23:02:26,411] {processor.py:641} INFO - Processing file /home/igor/Documents/airflowalura/dags/dados_climaticos.py for tasks to queue
[2022-12-13 23:02:26,412] {logging_mixin.py:115} INFO - [2022-12-13 23:02:26,412] {dagbag.py:507} INFO - Filling up the DagBag from /home/igor/Documents/airflowalura/dags/dados_climaticos.py
[2022-12-13 23:02:34,674] {logging_mixin.py:115} INFO - [2022-12-13 23:02:34,613] {dagbag.py:320} ERROR - Failed to import: /home/igor/Documents/airflowalura/dags/dados_climaticos.py
Traceback (most recent call last):
  File "/home/igor/Documents/airflowalura/venv/lib/python3.9/site-packages/airflow/models/dagbag.py", line 317, in parse
    loader.exec_module(new_module)
  File "<frozen importlib._bootstrap_external>", line 850, in exec_module
  File "<frozen importlib._bootstrap>", line 228, in _call_with_frames_removed
  File "/home/igor/Documents/airflowalura/dags/dados_climaticos.py", line 40, in <module>
    task_2 = PythonOperator(
  File "/home/igor/Documents/airflowalura/venv/lib/python3.9/site-packages/airflow/models/baseoperator.py", line 390, in apply_defaults
    result = func(self, **kwargs, default_args=default_args)
  File "/home/igor/Documents/airflowalura/venv/lib/python3.9/site-packages/airflow/operators/python.py", line 156, in __init__
    super().__init__(**kwargs)
  File "/home/igor/Documents/airflowalura/venv/lib/python3.9/site-packages/airflow/models/baseoperator.py", line 390, in apply_defaults
    result = func(self, **kwargs, default_args=default_args)
  File "/home/igor/Documents/airflowalura/venv/lib/python3.9/site-packages/airflow/models/baseoperator.py", line 754, in __init__
    validate_key(task_id)
  File "/home/igor/Documents/airflowalura/venv/lib/python3.9/site-packages/airflow/utils/helpers.py", line 63, in validate_key
    raise AirflowException(
airflow.exceptions.AirflowException: The key 'extrai dados' has to be made of alphanumeric characters, dashes, dots and underscores exclusively
[2022-12-13 23:02:34,682] {processor.py:653} WARNING - No viable dags retrieved from /home/igor/Documents/airflowalura/dags/dados_climaticos.py
[2022-12-13 23:02:34,974] {processor.py:161} INFO - Processing /home/igor/Documents/airflowalura/dags/dados_climaticos.py took 8.593 seconds
[2022-12-13 23:03:31,756] {processor.py:153} INFO - Started process (PID=35803) to work on /home/igor/Documents/airflowalura/dags/dados_climaticos.py
[2022-12-13 23:03:31,772] {processor.py:641} INFO - Processing file /home/igor/Documents/airflowalura/dags/dados_climaticos.py for tasks to queue
[2022-12-13 23:03:31,773] {logging_mixin.py:115} INFO - [2022-12-13 23:03:31,773] {dagbag.py:507} INFO - Filling up the DagBag from /home/igor/Documents/airflowalura/dags/dados_climaticos.py
[2022-12-13 23:03:38,808] {logging_mixin.py:115} INFO - [2022-12-13 23:03:38,768] {dagbag.py:320} ERROR - Failed to import: /home/igor/Documents/airflowalura/dags/dados_climaticos.py
Traceback (most recent call last):
  File "/home/igor/Documents/airflowalura/venv/lib/python3.9/site-packages/airflow/models/dagbag.py", line 317, in parse
    loader.exec_module(new_module)
  File "<frozen importlib._bootstrap_external>", line 850, in exec_module
  File "<frozen importlib._bootstrap>", line 228, in _call_with_frames_removed
  File "/home/igor/Documents/airflowalura/dags/dados_climaticos.py", line 40, in <module>
    task_2 = PythonOperator(
  File "/home/igor/Documents/airflowalura/venv/lib/python3.9/site-packages/airflow/models/baseoperator.py", line 390, in apply_defaults
    result = func(self, **kwargs, default_args=default_args)
  File "/home/igor/Documents/airflowalura/venv/lib/python3.9/site-packages/airflow/operators/python.py", line 156, in __init__
    super().__init__(**kwargs)
  File "/home/igor/Documents/airflowalura/venv/lib/python3.9/site-packages/airflow/models/baseoperator.py", line 390, in apply_defaults
    result = func(self, **kwargs, default_args=default_args)
  File "/home/igor/Documents/airflowalura/venv/lib/python3.9/site-packages/airflow/models/baseoperator.py", line 754, in __init__
    validate_key(task_id)
  File "/home/igor/Documents/airflowalura/venv/lib/python3.9/site-packages/airflow/utils/helpers.py", line 63, in validate_key
    raise AirflowException(
airflow.exceptions.AirflowException: The key 'extrai dados' has to be made of alphanumeric characters, dashes, dots and underscores exclusively
[2022-12-13 23:03:38,810] {processor.py:653} WARNING - No viable dags retrieved from /home/igor/Documents/airflowalura/dags/dados_climaticos.py
[2022-12-13 23:03:38,998] {processor.py:161} INFO - Processing /home/igor/Documents/airflowalura/dags/dados_climaticos.py took 7.256 seconds
[2022-12-13 23:04:35,474] {processor.py:153} INFO - Started process (PID=35937) to work on /home/igor/Documents/airflowalura/dags/dados_climaticos.py
[2022-12-13 23:04:35,497] {processor.py:641} INFO - Processing file /home/igor/Documents/airflowalura/dags/dados_climaticos.py for tasks to queue
[2022-12-13 23:04:35,499] {logging_mixin.py:115} INFO - [2022-12-13 23:04:35,498] {dagbag.py:507} INFO - Filling up the DagBag from /home/igor/Documents/airflowalura/dags/dados_climaticos.py
[2022-12-13 23:04:43,087] {logging_mixin.py:115} INFO - [2022-12-13 23:04:42,967] {dagbag.py:320} ERROR - Failed to import: /home/igor/Documents/airflowalura/dags/dados_climaticos.py
Traceback (most recent call last):
  File "/home/igor/Documents/airflowalura/venv/lib/python3.9/site-packages/airflow/models/dagbag.py", line 317, in parse
    loader.exec_module(new_module)
  File "<frozen importlib._bootstrap_external>", line 850, in exec_module
  File "<frozen importlib._bootstrap>", line 228, in _call_with_frames_removed
  File "/home/igor/Documents/airflowalura/dags/dados_climaticos.py", line 40, in <module>
    task_2 = PythonOperator(
  File "/home/igor/Documents/airflowalura/venv/lib/python3.9/site-packages/airflow/models/baseoperator.py", line 390, in apply_defaults
    result = func(self, **kwargs, default_args=default_args)
  File "/home/igor/Documents/airflowalura/venv/lib/python3.9/site-packages/airflow/operators/python.py", line 156, in __init__
    super().__init__(**kwargs)
  File "/home/igor/Documents/airflowalura/venv/lib/python3.9/site-packages/airflow/models/baseoperator.py", line 390, in apply_defaults
    result = func(self, **kwargs, default_args=default_args)
  File "/home/igor/Documents/airflowalura/venv/lib/python3.9/site-packages/airflow/models/baseoperator.py", line 754, in __init__
    validate_key(task_id)
  File "/home/igor/Documents/airflowalura/venv/lib/python3.9/site-packages/airflow/utils/helpers.py", line 63, in validate_key
    raise AirflowException(
airflow.exceptions.AirflowException: The key 'extrai dados' has to be made of alphanumeric characters, dashes, dots and underscores exclusively
[2022-12-13 23:04:43,094] {processor.py:653} WARNING - No viable dags retrieved from /home/igor/Documents/airflowalura/dags/dados_climaticos.py
[2022-12-13 23:04:43,279] {processor.py:161} INFO - Processing /home/igor/Documents/airflowalura/dags/dados_climaticos.py took 7.814 seconds
[2022-12-13 23:05:31,040] {processor.py:153} INFO - Started process (PID=36078) to work on /home/igor/Documents/airflowalura/dags/dados_climaticos.py
[2022-12-13 23:05:31,042] {processor.py:641} INFO - Processing file /home/igor/Documents/airflowalura/dags/dados_climaticos.py for tasks to queue
[2022-12-13 23:05:31,048] {logging_mixin.py:115} INFO - [2022-12-13 23:05:31,048] {dagbag.py:507} INFO - Filling up the DagBag from /home/igor/Documents/airflowalura/dags/dados_climaticos.py
[2022-12-13 23:05:38,322] {logging_mixin.py:115} INFO - [2022-12-13 23:05:38,266] {dagbag.py:320} ERROR - Failed to import: /home/igor/Documents/airflowalura/dags/dados_climaticos.py
Traceback (most recent call last):
  File "/home/igor/Documents/airflowalura/venv/lib/python3.9/site-packages/airflow/models/dagbag.py", line 317, in parse
    loader.exec_module(new_module)
  File "<frozen importlib._bootstrap_external>", line 850, in exec_module
  File "<frozen importlib._bootstrap>", line 228, in _call_with_frames_removed
  File "/home/igor/Documents/airflowalura/dags/dados_climaticos.py", line 40, in <module>
    task_2 = PythonOperator(
  File "/home/igor/Documents/airflowalura/venv/lib/python3.9/site-packages/airflow/models/baseoperator.py", line 390, in apply_defaults
    result = func(self, **kwargs, default_args=default_args)
  File "/home/igor/Documents/airflowalura/venv/lib/python3.9/site-packages/airflow/operators/python.py", line 156, in __init__
    super().__init__(**kwargs)
  File "/home/igor/Documents/airflowalura/venv/lib/python3.9/site-packages/airflow/models/baseoperator.py", line 390, in apply_defaults
    result = func(self, **kwargs, default_args=default_args)
  File "/home/igor/Documents/airflowalura/venv/lib/python3.9/site-packages/airflow/models/baseoperator.py", line 754, in __init__
    validate_key(task_id)
  File "/home/igor/Documents/airflowalura/venv/lib/python3.9/site-packages/airflow/utils/helpers.py", line 63, in validate_key
    raise AirflowException(
airflow.exceptions.AirflowException: The key 'extrai dados' has to be made of alphanumeric characters, dashes, dots and underscores exclusively
[2022-12-13 23:05:38,326] {processor.py:653} WARNING - No viable dags retrieved from /home/igor/Documents/airflowalura/dags/dados_climaticos.py
[2022-12-13 23:05:38,446] {processor.py:161} INFO - Processing /home/igor/Documents/airflowalura/dags/dados_climaticos.py took 7.442 seconds
[2022-12-13 23:06:29,602] {processor.py:153} INFO - Started process (PID=36178) to work on /home/igor/Documents/airflowalura/dags/dados_climaticos.py
[2022-12-13 23:06:29,610] {processor.py:641} INFO - Processing file /home/igor/Documents/airflowalura/dags/dados_climaticos.py for tasks to queue
[2022-12-13 23:06:29,614] {logging_mixin.py:115} INFO - [2022-12-13 23:06:29,613] {dagbag.py:507} INFO - Filling up the DagBag from /home/igor/Documents/airflowalura/dags/dados_climaticos.py
[2022-12-13 23:06:37,086] {logging_mixin.py:115} INFO - [2022-12-13 23:06:37,046] {dagbag.py:320} ERROR - Failed to import: /home/igor/Documents/airflowalura/dags/dados_climaticos.py
Traceback (most recent call last):
  File "/home/igor/Documents/airflowalura/venv/lib/python3.9/site-packages/airflow/models/dagbag.py", line 317, in parse
    loader.exec_module(new_module)
  File "<frozen importlib._bootstrap_external>", line 850, in exec_module
  File "<frozen importlib._bootstrap>", line 228, in _call_with_frames_removed
  File "/home/igor/Documents/airflowalura/dags/dados_climaticos.py", line 40, in <module>
    task_2 = PythonOperator(
  File "/home/igor/Documents/airflowalura/venv/lib/python3.9/site-packages/airflow/models/baseoperator.py", line 390, in apply_defaults
    result = func(self, **kwargs, default_args=default_args)
  File "/home/igor/Documents/airflowalura/venv/lib/python3.9/site-packages/airflow/operators/python.py", line 156, in __init__
    super().__init__(**kwargs)
  File "/home/igor/Documents/airflowalura/venv/lib/python3.9/site-packages/airflow/models/baseoperator.py", line 390, in apply_defaults
    result = func(self, **kwargs, default_args=default_args)
  File "/home/igor/Documents/airflowalura/venv/lib/python3.9/site-packages/airflow/models/baseoperator.py", line 754, in __init__
    validate_key(task_id)
  File "/home/igor/Documents/airflowalura/venv/lib/python3.9/site-packages/airflow/utils/helpers.py", line 63, in validate_key
    raise AirflowException(
airflow.exceptions.AirflowException: The key 'extrai dados' has to be made of alphanumeric characters, dashes, dots and underscores exclusively
[2022-12-13 23:06:37,091] {processor.py:653} WARNING - No viable dags retrieved from /home/igor/Documents/airflowalura/dags/dados_climaticos.py
[2022-12-13 23:06:37,356] {processor.py:161} INFO - Processing /home/igor/Documents/airflowalura/dags/dados_climaticos.py took 7.810 seconds
[2022-12-13 23:07:36,430] {processor.py:153} INFO - Started process (PID=36289) to work on /home/igor/Documents/airflowalura/dags/dados_climaticos.py
[2022-12-13 23:07:36,449] {processor.py:641} INFO - Processing file /home/igor/Documents/airflowalura/dags/dados_climaticos.py for tasks to queue
[2022-12-13 23:07:36,451] {logging_mixin.py:115} INFO - [2022-12-13 23:07:36,450] {dagbag.py:507} INFO - Filling up the DagBag from /home/igor/Documents/airflowalura/dags/dados_climaticos.py
[2022-12-13 23:07:41,958] {logging_mixin.py:115} INFO - [2022-12-13 23:07:41,934] {dagbag.py:320} ERROR - Failed to import: /home/igor/Documents/airflowalura/dags/dados_climaticos.py
Traceback (most recent call last):
  File "/home/igor/Documents/airflowalura/venv/lib/python3.9/site-packages/airflow/models/dagbag.py", line 317, in parse
    loader.exec_module(new_module)
  File "<frozen importlib._bootstrap_external>", line 850, in exec_module
  File "<frozen importlib._bootstrap>", line 228, in _call_with_frames_removed
  File "/home/igor/Documents/airflowalura/dags/dados_climaticos.py", line 40, in <module>
    task_2 = PythonOperator(
  File "/home/igor/Documents/airflowalura/venv/lib/python3.9/site-packages/airflow/models/baseoperator.py", line 390, in apply_defaults
    result = func(self, **kwargs, default_args=default_args)
  File "/home/igor/Documents/airflowalura/venv/lib/python3.9/site-packages/airflow/operators/python.py", line 156, in __init__
    super().__init__(**kwargs)
  File "/home/igor/Documents/airflowalura/venv/lib/python3.9/site-packages/airflow/models/baseoperator.py", line 390, in apply_defaults
    result = func(self, **kwargs, default_args=default_args)
  File "/home/igor/Documents/airflowalura/venv/lib/python3.9/site-packages/airflow/models/baseoperator.py", line 754, in __init__
    validate_key(task_id)
  File "/home/igor/Documents/airflowalura/venv/lib/python3.9/site-packages/airflow/utils/helpers.py", line 63, in validate_key
    raise AirflowException(
airflow.exceptions.AirflowException: The key 'extrai dados' has to be made of alphanumeric characters, dashes, dots and underscores exclusively
[2022-12-13 23:07:41,971] {processor.py:653} WARNING - No viable dags retrieved from /home/igor/Documents/airflowalura/dags/dados_climaticos.py
[2022-12-13 23:07:42,123] {processor.py:161} INFO - Processing /home/igor/Documents/airflowalura/dags/dados_climaticos.py took 5.700 seconds
[2022-12-13 23:09:18,679] {processor.py:153} INFO - Started process (PID=36440) to work on /home/igor/Documents/airflowalura/dags/dados_climaticos.py
[2022-12-13 23:09:18,684] {processor.py:641} INFO - Processing file /home/igor/Documents/airflowalura/dags/dados_climaticos.py for tasks to queue
[2022-12-13 23:09:18,697] {logging_mixin.py:115} INFO - [2022-12-13 23:09:18,696] {dagbag.py:507} INFO - Filling up the DagBag from /home/igor/Documents/airflowalura/dags/dados_climaticos.py
[2022-12-13 23:09:29,493] {logging_mixin.py:115} INFO - [2022-12-13 23:09:29,445] {dagbag.py:320} ERROR - Failed to import: /home/igor/Documents/airflowalura/dags/dados_climaticos.py
Traceback (most recent call last):
  File "/home/igor/Documents/airflowalura/venv/lib/python3.9/site-packages/airflow/models/dagbag.py", line 317, in parse
    loader.exec_module(new_module)
  File "<frozen importlib._bootstrap_external>", line 850, in exec_module
  File "<frozen importlib._bootstrap>", line 228, in _call_with_frames_removed
  File "/home/igor/Documents/airflowalura/dags/dados_climaticos.py", line 40, in <module>
    task_2 = PythonOperator(
  File "/home/igor/Documents/airflowalura/venv/lib/python3.9/site-packages/airflow/models/baseoperator.py", line 390, in apply_defaults
    result = func(self, **kwargs, default_args=default_args)
  File "/home/igor/Documents/airflowalura/venv/lib/python3.9/site-packages/airflow/operators/python.py", line 156, in __init__
    super().__init__(**kwargs)
  File "/home/igor/Documents/airflowalura/venv/lib/python3.9/site-packages/airflow/models/baseoperator.py", line 390, in apply_defaults
    result = func(self, **kwargs, default_args=default_args)
  File "/home/igor/Documents/airflowalura/venv/lib/python3.9/site-packages/airflow/models/baseoperator.py", line 754, in __init__
    validate_key(task_id)
  File "/home/igor/Documents/airflowalura/venv/lib/python3.9/site-packages/airflow/utils/helpers.py", line 63, in validate_key
    raise AirflowException(
airflow.exceptions.AirflowException: The key 'extrai dados' has to be made of alphanumeric characters, dashes, dots and underscores exclusively
[2022-12-13 23:09:29,522] {processor.py:653} WARNING - No viable dags retrieved from /home/igor/Documents/airflowalura/dags/dados_climaticos.py
[2022-12-13 23:09:29,837] {processor.py:161} INFO - Processing /home/igor/Documents/airflowalura/dags/dados_climaticos.py took 11.170 seconds
[2022-12-13 23:11:18,546] {processor.py:153} INFO - Started process (PID=36612) to work on /home/igor/Documents/airflowalura/dags/dados_climaticos.py
[2022-12-13 23:11:18,571] {processor.py:641} INFO - Processing file /home/igor/Documents/airflowalura/dags/dados_climaticos.py for tasks to queue
[2022-12-13 23:11:18,580] {logging_mixin.py:115} INFO - [2022-12-13 23:11:18,579] {dagbag.py:507} INFO - Filling up the DagBag from /home/igor/Documents/airflowalura/dags/dados_climaticos.py
[2022-12-13 23:11:27,194] {logging_mixin.py:115} INFO - [2022-12-13 23:11:27,137] {dagbag.py:320} ERROR - Failed to import: /home/igor/Documents/airflowalura/dags/dados_climaticos.py
Traceback (most recent call last):
  File "/home/igor/Documents/airflowalura/venv/lib/python3.9/site-packages/airflow/models/dagbag.py", line 317, in parse
    loader.exec_module(new_module)
  File "<frozen importlib._bootstrap_external>", line 850, in exec_module
  File "<frozen importlib._bootstrap>", line 228, in _call_with_frames_removed
  File "/home/igor/Documents/airflowalura/dags/dados_climaticos.py", line 40, in <module>
    task_2 = PythonOperator(
  File "/home/igor/Documents/airflowalura/venv/lib/python3.9/site-packages/airflow/models/baseoperator.py", line 390, in apply_defaults
    result = func(self, **kwargs, default_args=default_args)
  File "/home/igor/Documents/airflowalura/venv/lib/python3.9/site-packages/airflow/operators/python.py", line 156, in __init__
    super().__init__(**kwargs)
  File "/home/igor/Documents/airflowalura/venv/lib/python3.9/site-packages/airflow/models/baseoperator.py", line 390, in apply_defaults
    result = func(self, **kwargs, default_args=default_args)
  File "/home/igor/Documents/airflowalura/venv/lib/python3.9/site-packages/airflow/models/baseoperator.py", line 754, in __init__
    validate_key(task_id)
  File "/home/igor/Documents/airflowalura/venv/lib/python3.9/site-packages/airflow/utils/helpers.py", line 63, in validate_key
    raise AirflowException(
airflow.exceptions.AirflowException: The key 'extrai dados' has to be made of alphanumeric characters, dashes, dots and underscores exclusively
[2022-12-13 23:11:27,205] {processor.py:653} WARNING - No viable dags retrieved from /home/igor/Documents/airflowalura/dags/dados_climaticos.py
[2022-12-13 23:11:27,505] {processor.py:161} INFO - Processing /home/igor/Documents/airflowalura/dags/dados_climaticos.py took 8.995 seconds
[2022-12-13 23:12:53,715] {processor.py:153} INFO - Started process (PID=36929) to work on /home/igor/Documents/airflowalura/dags/dados_climaticos.py
[2022-12-13 23:12:53,726] {processor.py:641} INFO - Processing file /home/igor/Documents/airflowalura/dags/dados_climaticos.py for tasks to queue
[2022-12-13 23:12:53,736] {logging_mixin.py:115} INFO - [2022-12-13 23:12:53,736] {dagbag.py:507} INFO - Filling up the DagBag from /home/igor/Documents/airflowalura/dags/dados_climaticos.py
[2022-12-13 23:12:59,672] {logging_mixin.py:115} INFO - [2022-12-13 23:12:59,641] {dagbag.py:320} ERROR - Failed to import: /home/igor/Documents/airflowalura/dags/dados_climaticos.py
Traceback (most recent call last):
  File "/home/igor/Documents/airflowalura/venv/lib/python3.9/site-packages/airflow/models/dagbag.py", line 317, in parse
    loader.exec_module(new_module)
  File "<frozen importlib._bootstrap_external>", line 850, in exec_module
  File "<frozen importlib._bootstrap>", line 228, in _call_with_frames_removed
  File "/home/igor/Documents/airflowalura/dags/dados_climaticos.py", line 40, in <module>
    task_2 = PythonOperator(
  File "/home/igor/Documents/airflowalura/venv/lib/python3.9/site-packages/airflow/models/baseoperator.py", line 390, in apply_defaults
    result = func(self, **kwargs, default_args=default_args)
  File "/home/igor/Documents/airflowalura/venv/lib/python3.9/site-packages/airflow/operators/python.py", line 156, in __init__
    super().__init__(**kwargs)
  File "/home/igor/Documents/airflowalura/venv/lib/python3.9/site-packages/airflow/models/baseoperator.py", line 390, in apply_defaults
    result = func(self, **kwargs, default_args=default_args)
  File "/home/igor/Documents/airflowalura/venv/lib/python3.9/site-packages/airflow/models/baseoperator.py", line 754, in __init__
    validate_key(task_id)
  File "/home/igor/Documents/airflowalura/venv/lib/python3.9/site-packages/airflow/utils/helpers.py", line 63, in validate_key
    raise AirflowException(
airflow.exceptions.AirflowException: The key 'extrai dados' has to be made of alphanumeric characters, dashes, dots and underscores exclusively
[2022-12-13 23:12:59,676] {processor.py:653} WARNING - No viable dags retrieved from /home/igor/Documents/airflowalura/dags/dados_climaticos.py
[2022-12-13 23:12:59,820] {processor.py:161} INFO - Processing /home/igor/Documents/airflowalura/dags/dados_climaticos.py took 6.125 seconds
[2022-12-13 23:13:46,241] {processor.py:153} INFO - Started process (PID=37105) to work on /home/igor/Documents/airflowalura/dags/dados_climaticos.py
[2022-12-13 23:13:46,255] {processor.py:641} INFO - Processing file /home/igor/Documents/airflowalura/dags/dados_climaticos.py for tasks to queue
[2022-12-13 23:13:46,256] {logging_mixin.py:115} INFO - [2022-12-13 23:13:46,256] {dagbag.py:507} INFO - Filling up the DagBag from /home/igor/Documents/airflowalura/dags/dados_climaticos.py
[2022-12-13 23:13:50,820] {logging_mixin.py:115} INFO - [2022-12-13 23:13:50,790] {dagbag.py:320} ERROR - Failed to import: /home/igor/Documents/airflowalura/dags/dados_climaticos.py
Traceback (most recent call last):
  File "/home/igor/Documents/airflowalura/venv/lib/python3.9/site-packages/airflow/models/dagbag.py", line 317, in parse
    loader.exec_module(new_module)
  File "<frozen importlib._bootstrap_external>", line 850, in exec_module
  File "<frozen importlib._bootstrap>", line 228, in _call_with_frames_removed
  File "/home/igor/Documents/airflowalura/dags/dados_climaticos.py", line 40, in <module>
    task_2 = PythonOperator(
  File "/home/igor/Documents/airflowalura/venv/lib/python3.9/site-packages/airflow/models/baseoperator.py", line 390, in apply_defaults
    result = func(self, **kwargs, default_args=default_args)
  File "/home/igor/Documents/airflowalura/venv/lib/python3.9/site-packages/airflow/operators/python.py", line 156, in __init__
    super().__init__(**kwargs)
  File "/home/igor/Documents/airflowalura/venv/lib/python3.9/site-packages/airflow/models/baseoperator.py", line 390, in apply_defaults
    result = func(self, **kwargs, default_args=default_args)
  File "/home/igor/Documents/airflowalura/venv/lib/python3.9/site-packages/airflow/models/baseoperator.py", line 754, in __init__
    validate_key(task_id)
  File "/home/igor/Documents/airflowalura/venv/lib/python3.9/site-packages/airflow/utils/helpers.py", line 63, in validate_key
    raise AirflowException(
airflow.exceptions.AirflowException: The key 'extrai dados' has to be made of alphanumeric characters, dashes, dots and underscores exclusively
[2022-12-13 23:13:50,820] {processor.py:653} WARNING - No viable dags retrieved from /home/igor/Documents/airflowalura/dags/dados_climaticos.py
[2022-12-13 23:13:50,900] {processor.py:161} INFO - Processing /home/igor/Documents/airflowalura/dags/dados_climaticos.py took 4.689 seconds
[2022-12-13 23:14:29,986] {processor.py:153} INFO - Started process (PID=37207) to work on /home/igor/Documents/airflowalura/dags/dados_climaticos.py
[2022-12-13 23:14:30,010] {processor.py:641} INFO - Processing file /home/igor/Documents/airflowalura/dags/dados_climaticos.py for tasks to queue
[2022-12-13 23:14:30,013] {logging_mixin.py:115} INFO - [2022-12-13 23:14:30,012] {dagbag.py:507} INFO - Filling up the DagBag from /home/igor/Documents/airflowalura/dags/dados_climaticos.py
[2022-12-13 23:14:34,625] {logging_mixin.py:115} INFO - [2022-12-13 23:14:34,592] {dagbag.py:320} ERROR - Failed to import: /home/igor/Documents/airflowalura/dags/dados_climaticos.py
Traceback (most recent call last):
  File "/home/igor/Documents/airflowalura/venv/lib/python3.9/site-packages/airflow/models/dagbag.py", line 317, in parse
    loader.exec_module(new_module)
  File "<frozen importlib._bootstrap_external>", line 850, in exec_module
  File "<frozen importlib._bootstrap>", line 228, in _call_with_frames_removed
  File "/home/igor/Documents/airflowalura/dags/dados_climaticos.py", line 40, in <module>
    task_2 = PythonOperator(
  File "/home/igor/Documents/airflowalura/venv/lib/python3.9/site-packages/airflow/models/baseoperator.py", line 390, in apply_defaults
    result = func(self, **kwargs, default_args=default_args)
  File "/home/igor/Documents/airflowalura/venv/lib/python3.9/site-packages/airflow/operators/python.py", line 156, in __init__
    super().__init__(**kwargs)
  File "/home/igor/Documents/airflowalura/venv/lib/python3.9/site-packages/airflow/models/baseoperator.py", line 390, in apply_defaults
    result = func(self, **kwargs, default_args=default_args)
  File "/home/igor/Documents/airflowalura/venv/lib/python3.9/site-packages/airflow/models/baseoperator.py", line 754, in __init__
    validate_key(task_id)
  File "/home/igor/Documents/airflowalura/venv/lib/python3.9/site-packages/airflow/utils/helpers.py", line 63, in validate_key
    raise AirflowException(
airflow.exceptions.AirflowException: The key 'extrai dados' has to be made of alphanumeric characters, dashes, dots and underscores exclusively
[2022-12-13 23:14:34,632] {processor.py:653} WARNING - No viable dags retrieved from /home/igor/Documents/airflowalura/dags/dados_climaticos.py
[2022-12-13 23:14:34,773] {processor.py:161} INFO - Processing /home/igor/Documents/airflowalura/dags/dados_climaticos.py took 4.831 seconds
[2022-12-13 23:15:17,122] {processor.py:153} INFO - Started process (PID=37316) to work on /home/igor/Documents/airflowalura/dags/dados_climaticos.py
[2022-12-13 23:15:17,136] {processor.py:641} INFO - Processing file /home/igor/Documents/airflowalura/dags/dados_climaticos.py for tasks to queue
[2022-12-13 23:15:17,138] {logging_mixin.py:115} INFO - [2022-12-13 23:15:17,138] {dagbag.py:507} INFO - Filling up the DagBag from /home/igor/Documents/airflowalura/dags/dados_climaticos.py
[2022-12-13 23:15:22,272] {logging_mixin.py:115} INFO - [2022-12-13 23:15:22,250] {dagbag.py:320} ERROR - Failed to import: /home/igor/Documents/airflowalura/dags/dados_climaticos.py
Traceback (most recent call last):
  File "/home/igor/Documents/airflowalura/venv/lib/python3.9/site-packages/airflow/models/dagbag.py", line 317, in parse
    loader.exec_module(new_module)
  File "<frozen importlib._bootstrap_external>", line 850, in exec_module
  File "<frozen importlib._bootstrap>", line 228, in _call_with_frames_removed
  File "/home/igor/Documents/airflowalura/dags/dados_climaticos.py", line 40, in <module>
    task_2 = PythonOperator(
  File "/home/igor/Documents/airflowalura/venv/lib/python3.9/site-packages/airflow/models/baseoperator.py", line 390, in apply_defaults
    result = func(self, **kwargs, default_args=default_args)
  File "/home/igor/Documents/airflowalura/venv/lib/python3.9/site-packages/airflow/operators/python.py", line 156, in __init__
    super().__init__(**kwargs)
  File "/home/igor/Documents/airflowalura/venv/lib/python3.9/site-packages/airflow/models/baseoperator.py", line 390, in apply_defaults
    result = func(self, **kwargs, default_args=default_args)
  File "/home/igor/Documents/airflowalura/venv/lib/python3.9/site-packages/airflow/models/baseoperator.py", line 754, in __init__
    validate_key(task_id)
  File "/home/igor/Documents/airflowalura/venv/lib/python3.9/site-packages/airflow/utils/helpers.py", line 63, in validate_key
    raise AirflowException(
airflow.exceptions.AirflowException: The key 'extrai dados' has to be made of alphanumeric characters, dashes, dots and underscores exclusively
[2022-12-13 23:15:22,276] {processor.py:653} WARNING - No viable dags retrieved from /home/igor/Documents/airflowalura/dags/dados_climaticos.py
[2022-12-13 23:15:22,360] {processor.py:161} INFO - Processing /home/igor/Documents/airflowalura/dags/dados_climaticos.py took 5.265 seconds
[2022-12-13 23:16:04,387] {processor.py:153} INFO - Started process (PID=37421) to work on /home/igor/Documents/airflowalura/dags/dados_climaticos.py
[2022-12-13 23:16:05,876] {processor.py:641} INFO - Processing file /home/igor/Documents/airflowalura/dags/dados_climaticos.py for tasks to queue
[2022-12-13 23:16:05,878] {logging_mixin.py:115} INFO - [2022-12-13 23:16:05,878] {dagbag.py:507} INFO - Filling up the DagBag from /home/igor/Documents/airflowalura/dags/dados_climaticos.py
[2022-12-13 23:16:41,826] {logging_mixin.py:115} INFO - [2022-12-13 23:16:41,826] {timeout.py:67} ERROR - Process timed out, PID: 37421
[2022-12-13 23:16:42,773] {logging_mixin.py:115} INFO - [2022-12-13 23:16:41,832] {dagbag.py:320} ERROR - Failed to import: /home/igor/Documents/airflowalura/dags/dados_climaticos.py
Traceback (most recent call last):
  File "/home/igor/Documents/airflowalura/venv/lib/python3.9/site-packages/airflow/models/dagbag.py", line 317, in parse
    loader.exec_module(new_module)
  File "<frozen importlib._bootstrap_external>", line 850, in exec_module
  File "<frozen importlib._bootstrap>", line 228, in _call_with_frames_removed
  File "/home/igor/Documents/airflowalura/dags/dados_climaticos.py", line 7, in <module>
    import pandas as pd
  File "<frozen importlib._bootstrap>", line 1007, in _find_and_load
  File "<frozen importlib._bootstrap>", line 986, in _find_and_load_unlocked
  File "<frozen importlib._bootstrap>", line 680, in _load_unlocked
  File "<frozen importlib._bootstrap_external>", line 846, in exec_module
  File "<frozen importlib._bootstrap_external>", line 941, in get_code
  File "<frozen importlib._bootstrap_external>", line 1040, in get_data
  File "/home/igor/Documents/airflowalura/venv/lib/python3.9/site-packages/airflow/utils/timeout.py", line 68, in handle_timeout
    raise AirflowTaskTimeout(self.error_message)
airflow.exceptions.AirflowTaskTimeout: DagBag import timeout for /home/igor/Documents/airflowalura/dags/dados_climaticos.py after 30.0s.
Please take a look at these docs to improve your DAG import time:
* https://airflow.apache.org/docs/apache-airflow/2.3.2/best-practices.html#top-level-python-code
* https://airflow.apache.org/docs/apache-airflow/2.3.2/best-practices.html#reducing-dag-complexity, PID: 37421
[2022-12-13 23:16:42,775] {processor.py:653} WARNING - No viable dags retrieved from /home/igor/Documents/airflowalura/dags/dados_climaticos.py
[2022-12-13 23:16:47,984] {processor.py:161} INFO - Processing /home/igor/Documents/airflowalura/dags/dados_climaticos.py took 43.607 seconds
[2022-12-13 23:18:00,586] {processor.py:153} INFO - Started process (PID=37560) to work on /home/igor/Documents/airflowalura/dags/dados_climaticos.py
[2022-12-13 23:18:00,598] {processor.py:641} INFO - Processing file /home/igor/Documents/airflowalura/dags/dados_climaticos.py for tasks to queue
[2022-12-13 23:18:00,600] {logging_mixin.py:115} INFO - [2022-12-13 23:18:00,599] {dagbag.py:507} INFO - Filling up the DagBag from /home/igor/Documents/airflowalura/dags/dados_climaticos.py
[2022-12-13 23:18:05,293] {logging_mixin.py:115} INFO - [2022-12-13 23:18:05,260] {dagbag.py:320} ERROR - Failed to import: /home/igor/Documents/airflowalura/dags/dados_climaticos.py
Traceback (most recent call last):
  File "/home/igor/Documents/airflowalura/venv/lib/python3.9/site-packages/airflow/models/dagbag.py", line 317, in parse
    loader.exec_module(new_module)
  File "<frozen importlib._bootstrap_external>", line 850, in exec_module
  File "<frozen importlib._bootstrap>", line 228, in _call_with_frames_removed
  File "/home/igor/Documents/airflowalura/dags/dados_climaticos.py", line 40, in <module>
    task_2 = PythonOperator(
  File "/home/igor/Documents/airflowalura/venv/lib/python3.9/site-packages/airflow/models/baseoperator.py", line 390, in apply_defaults
    result = func(self, **kwargs, default_args=default_args)
  File "/home/igor/Documents/airflowalura/venv/lib/python3.9/site-packages/airflow/operators/python.py", line 156, in __init__
    super().__init__(**kwargs)
  File "/home/igor/Documents/airflowalura/venv/lib/python3.9/site-packages/airflow/models/baseoperator.py", line 390, in apply_defaults
    result = func(self, **kwargs, default_args=default_args)
  File "/home/igor/Documents/airflowalura/venv/lib/python3.9/site-packages/airflow/models/baseoperator.py", line 754, in __init__
    validate_key(task_id)
  File "/home/igor/Documents/airflowalura/venv/lib/python3.9/site-packages/airflow/utils/helpers.py", line 63, in validate_key
    raise AirflowException(
airflow.exceptions.AirflowException: The key 'extrai dados' has to be made of alphanumeric characters, dashes, dots and underscores exclusively
[2022-12-13 23:18:05,297] {processor.py:653} WARNING - No viable dags retrieved from /home/igor/Documents/airflowalura/dags/dados_climaticos.py
[2022-12-13 23:18:05,459] {processor.py:161} INFO - Processing /home/igor/Documents/airflowalura/dags/dados_climaticos.py took 4.906 seconds
[2022-12-13 23:18:46,216] {processor.py:153} INFO - Started process (PID=37671) to work on /home/igor/Documents/airflowalura/dags/dados_climaticos.py
[2022-12-13 23:18:46,240] {processor.py:641} INFO - Processing file /home/igor/Documents/airflowalura/dags/dados_climaticos.py for tasks to queue
[2022-12-13 23:18:46,241] {logging_mixin.py:115} INFO - [2022-12-13 23:18:46,241] {dagbag.py:507} INFO - Filling up the DagBag from /home/igor/Documents/airflowalura/dags/dados_climaticos.py
[2022-12-13 23:18:51,529] {logging_mixin.py:115} INFO - [2022-12-13 23:18:51,502] {dagbag.py:320} ERROR - Failed to import: /home/igor/Documents/airflowalura/dags/dados_climaticos.py
Traceback (most recent call last):
  File "/home/igor/Documents/airflowalura/venv/lib/python3.9/site-packages/airflow/models/dagbag.py", line 317, in parse
    loader.exec_module(new_module)
  File "<frozen importlib._bootstrap_external>", line 850, in exec_module
  File "<frozen importlib._bootstrap>", line 228, in _call_with_frames_removed
  File "/home/igor/Documents/airflowalura/dags/dados_climaticos.py", line 40, in <module>
    task_2 = PythonOperator(
  File "/home/igor/Documents/airflowalura/venv/lib/python3.9/site-packages/airflow/models/baseoperator.py", line 390, in apply_defaults
    result = func(self, **kwargs, default_args=default_args)
  File "/home/igor/Documents/airflowalura/venv/lib/python3.9/site-packages/airflow/operators/python.py", line 156, in __init__
    super().__init__(**kwargs)
  File "/home/igor/Documents/airflowalura/venv/lib/python3.9/site-packages/airflow/models/baseoperator.py", line 390, in apply_defaults
    result = func(self, **kwargs, default_args=default_args)
  File "/home/igor/Documents/airflowalura/venv/lib/python3.9/site-packages/airflow/models/baseoperator.py", line 754, in __init__
    validate_key(task_id)
  File "/home/igor/Documents/airflowalura/venv/lib/python3.9/site-packages/airflow/utils/helpers.py", line 63, in validate_key
    raise AirflowException(
airflow.exceptions.AirflowException: The key 'extrai dados' has to be made of alphanumeric characters, dashes, dots and underscores exclusively
[2022-12-13 23:18:51,530] {processor.py:653} WARNING - No viable dags retrieved from /home/igor/Documents/airflowalura/dags/dados_climaticos.py
[2022-12-13 23:18:51,711] {processor.py:161} INFO - Processing /home/igor/Documents/airflowalura/dags/dados_climaticos.py took 5.533 seconds
[2022-12-13 23:19:28,111] {processor.py:153} INFO - Started process (PID=37776) to work on /home/igor/Documents/airflowalura/dags/dados_climaticos.py
[2022-12-13 23:19:28,125] {processor.py:641} INFO - Processing file /home/igor/Documents/airflowalura/dags/dados_climaticos.py for tasks to queue
[2022-12-13 23:19:28,136] {logging_mixin.py:115} INFO - [2022-12-13 23:19:28,136] {dagbag.py:507} INFO - Filling up the DagBag from /home/igor/Documents/airflowalura/dags/dados_climaticos.py
[2022-12-13 23:19:32,198] {logging_mixin.py:115} INFO - [2022-12-13 23:19:32,178] {dagbag.py:320} ERROR - Failed to import: /home/igor/Documents/airflowalura/dags/dados_climaticos.py
Traceback (most recent call last):
  File "/home/igor/Documents/airflowalura/venv/lib/python3.9/site-packages/airflow/models/dagbag.py", line 317, in parse
    loader.exec_module(new_module)
  File "<frozen importlib._bootstrap_external>", line 850, in exec_module
  File "<frozen importlib._bootstrap>", line 228, in _call_with_frames_removed
  File "/home/igor/Documents/airflowalura/dags/dados_climaticos.py", line 40, in <module>
    task_2 = PythonOperator(
  File "/home/igor/Documents/airflowalura/venv/lib/python3.9/site-packages/airflow/models/baseoperator.py", line 390, in apply_defaults
    result = func(self, **kwargs, default_args=default_args)
  File "/home/igor/Documents/airflowalura/venv/lib/python3.9/site-packages/airflow/operators/python.py", line 156, in __init__
    super().__init__(**kwargs)
  File "/home/igor/Documents/airflowalura/venv/lib/python3.9/site-packages/airflow/models/baseoperator.py", line 390, in apply_defaults
    result = func(self, **kwargs, default_args=default_args)
  File "/home/igor/Documents/airflowalura/venv/lib/python3.9/site-packages/airflow/models/baseoperator.py", line 754, in __init__
    validate_key(task_id)
  File "/home/igor/Documents/airflowalura/venv/lib/python3.9/site-packages/airflow/utils/helpers.py", line 63, in validate_key
    raise AirflowException(
airflow.exceptions.AirflowException: The key 'extrai dados' has to be made of alphanumeric characters, dashes, dots and underscores exclusively
[2022-12-13 23:19:32,245] {processor.py:653} WARNING - No viable dags retrieved from /home/igor/Documents/airflowalura/dags/dados_climaticos.py
[2022-12-13 23:19:32,358] {processor.py:161} INFO - Processing /home/igor/Documents/airflowalura/dags/dados_climaticos.py took 4.284 seconds
[2022-12-13 23:20:06,445] {processor.py:153} INFO - Started process (PID=37867) to work on /home/igor/Documents/airflowalura/dags/dados_climaticos.py
[2022-12-13 23:20:06,460] {processor.py:641} INFO - Processing file /home/igor/Documents/airflowalura/dags/dados_climaticos.py for tasks to queue
[2022-12-13 23:20:06,462] {logging_mixin.py:115} INFO - [2022-12-13 23:20:06,462] {dagbag.py:507} INFO - Filling up the DagBag from /home/igor/Documents/airflowalura/dags/dados_climaticos.py
[2022-12-13 23:20:09,844] {logging_mixin.py:115} INFO - [2022-12-13 23:20:09,841] {dagbag.py:320} ERROR - Failed to import: /home/igor/Documents/airflowalura/dags/dados_climaticos.py
Traceback (most recent call last):
  File "/home/igor/Documents/airflowalura/venv/lib/python3.9/site-packages/airflow/models/dagbag.py", line 317, in parse
    loader.exec_module(new_module)
  File "<frozen importlib._bootstrap_external>", line 850, in exec_module
  File "<frozen importlib._bootstrap>", line 228, in _call_with_frames_removed
  File "/home/igor/Documents/airflowalura/dags/dados_climaticos.py", line 40, in <module>
    task_2 = PythonOperator(
  File "/home/igor/Documents/airflowalura/venv/lib/python3.9/site-packages/airflow/models/baseoperator.py", line 390, in apply_defaults
    result = func(self, **kwargs, default_args=default_args)
  File "/home/igor/Documents/airflowalura/venv/lib/python3.9/site-packages/airflow/operators/python.py", line 156, in __init__
    super().__init__(**kwargs)
  File "/home/igor/Documents/airflowalura/venv/lib/python3.9/site-packages/airflow/models/baseoperator.py", line 390, in apply_defaults
    result = func(self, **kwargs, default_args=default_args)
  File "/home/igor/Documents/airflowalura/venv/lib/python3.9/site-packages/airflow/models/baseoperator.py", line 754, in __init__
    validate_key(task_id)
  File "/home/igor/Documents/airflowalura/venv/lib/python3.9/site-packages/airflow/utils/helpers.py", line 63, in validate_key
    raise AirflowException(
airflow.exceptions.AirflowException: The key 'extrai dados' has to be made of alphanumeric characters, dashes, dots and underscores exclusively
[2022-12-13 23:20:09,844] {processor.py:653} WARNING - No viable dags retrieved from /home/igor/Documents/airflowalura/dags/dados_climaticos.py
[2022-12-13 23:20:09,939] {processor.py:161} INFO - Processing /home/igor/Documents/airflowalura/dags/dados_climaticos.py took 3.528 seconds
[2022-12-13 23:20:44,338] {processor.py:153} INFO - Started process (PID=37968) to work on /home/igor/Documents/airflowalura/dags/dados_climaticos.py
[2022-12-13 23:20:44,348] {processor.py:641} INFO - Processing file /home/igor/Documents/airflowalura/dags/dados_climaticos.py for tasks to queue
[2022-12-13 23:20:44,350] {logging_mixin.py:115} INFO - [2022-12-13 23:20:44,349] {dagbag.py:507} INFO - Filling up the DagBag from /home/igor/Documents/airflowalura/dags/dados_climaticos.py
[2022-12-13 23:20:47,386] {logging_mixin.py:115} INFO - [2022-12-13 23:20:47,384] {dagbag.py:320} ERROR - Failed to import: /home/igor/Documents/airflowalura/dags/dados_climaticos.py
Traceback (most recent call last):
  File "/home/igor/Documents/airflowalura/venv/lib/python3.9/site-packages/airflow/models/dagbag.py", line 317, in parse
    loader.exec_module(new_module)
  File "<frozen importlib._bootstrap_external>", line 850, in exec_module
  File "<frozen importlib._bootstrap>", line 228, in _call_with_frames_removed
  File "/home/igor/Documents/airflowalura/dags/dados_climaticos.py", line 40, in <module>
    task_2 = PythonOperator(
  File "/home/igor/Documents/airflowalura/venv/lib/python3.9/site-packages/airflow/models/baseoperator.py", line 390, in apply_defaults
    result = func(self, **kwargs, default_args=default_args)
  File "/home/igor/Documents/airflowalura/venv/lib/python3.9/site-packages/airflow/operators/python.py", line 156, in __init__
    super().__init__(**kwargs)
  File "/home/igor/Documents/airflowalura/venv/lib/python3.9/site-packages/airflow/models/baseoperator.py", line 390, in apply_defaults
    result = func(self, **kwargs, default_args=default_args)
  File "/home/igor/Documents/airflowalura/venv/lib/python3.9/site-packages/airflow/models/baseoperator.py", line 754, in __init__
    validate_key(task_id)
  File "/home/igor/Documents/airflowalura/venv/lib/python3.9/site-packages/airflow/utils/helpers.py", line 63, in validate_key
    raise AirflowException(
airflow.exceptions.AirflowException: The key 'extrai dados' has to be made of alphanumeric characters, dashes, dots and underscores exclusively
[2022-12-13 23:20:47,387] {processor.py:653} WARNING - No viable dags retrieved from /home/igor/Documents/airflowalura/dags/dados_climaticos.py
[2022-12-13 23:20:47,481] {processor.py:161} INFO - Processing /home/igor/Documents/airflowalura/dags/dados_climaticos.py took 3.161 seconds
[2022-12-13 23:21:19,619] {processor.py:153} INFO - Started process (PID=38061) to work on /home/igor/Documents/airflowalura/dags/dados_climaticos.py
[2022-12-13 23:21:19,630] {processor.py:641} INFO - Processing file /home/igor/Documents/airflowalura/dags/dados_climaticos.py for tasks to queue
[2022-12-13 23:21:19,637] {logging_mixin.py:115} INFO - [2022-12-13 23:21:19,636] {dagbag.py:507} INFO - Filling up the DagBag from /home/igor/Documents/airflowalura/dags/dados_climaticos.py
[2022-12-13 23:21:23,105] {logging_mixin.py:115} INFO - [2022-12-13 23:21:23,092] {dagbag.py:320} ERROR - Failed to import: /home/igor/Documents/airflowalura/dags/dados_climaticos.py
Traceback (most recent call last):
  File "/home/igor/Documents/airflowalura/venv/lib/python3.9/site-packages/airflow/models/dagbag.py", line 317, in parse
    loader.exec_module(new_module)
  File "<frozen importlib._bootstrap_external>", line 850, in exec_module
  File "<frozen importlib._bootstrap>", line 228, in _call_with_frames_removed
  File "/home/igor/Documents/airflowalura/dags/dados_climaticos.py", line 40, in <module>
    task_2 = PythonOperator(
  File "/home/igor/Documents/airflowalura/venv/lib/python3.9/site-packages/airflow/models/baseoperator.py", line 390, in apply_defaults
    result = func(self, **kwargs, default_args=default_args)
  File "/home/igor/Documents/airflowalura/venv/lib/python3.9/site-packages/airflow/operators/python.py", line 156, in __init__
    super().__init__(**kwargs)
  File "/home/igor/Documents/airflowalura/venv/lib/python3.9/site-packages/airflow/models/baseoperator.py", line 390, in apply_defaults
    result = func(self, **kwargs, default_args=default_args)
  File "/home/igor/Documents/airflowalura/venv/lib/python3.9/site-packages/airflow/models/baseoperator.py", line 754, in __init__
    validate_key(task_id)
  File "/home/igor/Documents/airflowalura/venv/lib/python3.9/site-packages/airflow/utils/helpers.py", line 63, in validate_key
    raise AirflowException(
airflow.exceptions.AirflowException: The key 'extrai dados' has to be made of alphanumeric characters, dashes, dots and underscores exclusively
[2022-12-13 23:21:23,116] {processor.py:653} WARNING - No viable dags retrieved from /home/igor/Documents/airflowalura/dags/dados_climaticos.py
[2022-12-13 23:21:23,248] {processor.py:161} INFO - Processing /home/igor/Documents/airflowalura/dags/dados_climaticos.py took 3.672 seconds
[2022-12-13 23:21:57,922] {processor.py:153} INFO - Started process (PID=38155) to work on /home/igor/Documents/airflowalura/dags/dados_climaticos.py
[2022-12-13 23:21:57,926] {processor.py:641} INFO - Processing file /home/igor/Documents/airflowalura/dags/dados_climaticos.py for tasks to queue
[2022-12-13 23:21:57,944] {logging_mixin.py:115} INFO - [2022-12-13 23:21:57,944] {dagbag.py:507} INFO - Filling up the DagBag from /home/igor/Documents/airflowalura/dags/dados_climaticos.py
[2022-12-13 23:22:01,724] {logging_mixin.py:115} INFO - [2022-12-13 23:22:01,715] {dagbag.py:320} ERROR - Failed to import: /home/igor/Documents/airflowalura/dags/dados_climaticos.py
Traceback (most recent call last):
  File "/home/igor/Documents/airflowalura/venv/lib/python3.9/site-packages/airflow/models/dagbag.py", line 317, in parse
    loader.exec_module(new_module)
  File "<frozen importlib._bootstrap_external>", line 850, in exec_module
  File "<frozen importlib._bootstrap>", line 228, in _call_with_frames_removed
  File "/home/igor/Documents/airflowalura/dags/dados_climaticos.py", line 40, in <module>
    task_2 = PythonOperator(
  File "/home/igor/Documents/airflowalura/venv/lib/python3.9/site-packages/airflow/models/baseoperator.py", line 390, in apply_defaults
    result = func(self, **kwargs, default_args=default_args)
  File "/home/igor/Documents/airflowalura/venv/lib/python3.9/site-packages/airflow/operators/python.py", line 156, in __init__
    super().__init__(**kwargs)
  File "/home/igor/Documents/airflowalura/venv/lib/python3.9/site-packages/airflow/models/baseoperator.py", line 390, in apply_defaults
    result = func(self, **kwargs, default_args=default_args)
  File "/home/igor/Documents/airflowalura/venv/lib/python3.9/site-packages/airflow/models/baseoperator.py", line 754, in __init__
    validate_key(task_id)
  File "/home/igor/Documents/airflowalura/venv/lib/python3.9/site-packages/airflow/utils/helpers.py", line 63, in validate_key
    raise AirflowException(
airflow.exceptions.AirflowException: The key 'extrai dados' has to be made of alphanumeric characters, dashes, dots and underscores exclusively
[2022-12-13 23:22:01,725] {processor.py:653} WARNING - No viable dags retrieved from /home/igor/Documents/airflowalura/dags/dados_climaticos.py
[2022-12-13 23:22:01,808] {processor.py:161} INFO - Processing /home/igor/Documents/airflowalura/dags/dados_climaticos.py took 3.926 seconds
[2022-12-13 23:22:37,056] {processor.py:153} INFO - Started process (PID=38287) to work on /home/igor/Documents/airflowalura/dags/dados_climaticos.py
[2022-12-13 23:22:37,060] {processor.py:641} INFO - Processing file /home/igor/Documents/airflowalura/dags/dados_climaticos.py for tasks to queue
[2022-12-13 23:22:37,062] {logging_mixin.py:115} INFO - [2022-12-13 23:22:37,062] {dagbag.py:507} INFO - Filling up the DagBag from /home/igor/Documents/airflowalura/dags/dados_climaticos.py
[2022-12-13 23:22:40,752] {logging_mixin.py:115} INFO - [2022-12-13 23:22:40,725] {dagbag.py:320} ERROR - Failed to import: /home/igor/Documents/airflowalura/dags/dados_climaticos.py
Traceback (most recent call last):
  File "/home/igor/Documents/airflowalura/venv/lib/python3.9/site-packages/airflow/models/dagbag.py", line 317, in parse
    loader.exec_module(new_module)
  File "<frozen importlib._bootstrap_external>", line 850, in exec_module
  File "<frozen importlib._bootstrap>", line 228, in _call_with_frames_removed
  File "/home/igor/Documents/airflowalura/dags/dados_climaticos.py", line 40, in <module>
    task_2 = PythonOperator(
  File "/home/igor/Documents/airflowalura/venv/lib/python3.9/site-packages/airflow/models/baseoperator.py", line 390, in apply_defaults
    result = func(self, **kwargs, default_args=default_args)
  File "/home/igor/Documents/airflowalura/venv/lib/python3.9/site-packages/airflow/operators/python.py", line 156, in __init__
    super().__init__(**kwargs)
  File "/home/igor/Documents/airflowalura/venv/lib/python3.9/site-packages/airflow/models/baseoperator.py", line 390, in apply_defaults
    result = func(self, **kwargs, default_args=default_args)
  File "/home/igor/Documents/airflowalura/venv/lib/python3.9/site-packages/airflow/models/baseoperator.py", line 754, in __init__
    validate_key(task_id)
  File "/home/igor/Documents/airflowalura/venv/lib/python3.9/site-packages/airflow/utils/helpers.py", line 63, in validate_key
    raise AirflowException(
airflow.exceptions.AirflowException: The key 'extrai dados' has to be made of alphanumeric characters, dashes, dots and underscores exclusively
[2022-12-13 23:22:40,756] {processor.py:653} WARNING - No viable dags retrieved from /home/igor/Documents/airflowalura/dags/dados_climaticos.py
[2022-12-13 23:22:40,880] {processor.py:161} INFO - Processing /home/igor/Documents/airflowalura/dags/dados_climaticos.py took 3.856 seconds
[2022-12-13 23:23:17,842] {processor.py:153} INFO - Started process (PID=38427) to work on /home/igor/Documents/airflowalura/dags/dados_climaticos.py
[2022-12-13 23:23:17,852] {processor.py:641} INFO - Processing file /home/igor/Documents/airflowalura/dags/dados_climaticos.py for tasks to queue
[2022-12-13 23:23:17,853] {logging_mixin.py:115} INFO - [2022-12-13 23:23:17,853] {dagbag.py:507} INFO - Filling up the DagBag from /home/igor/Documents/airflowalura/dags/dados_climaticos.py
[2022-12-13 23:23:21,961] {logging_mixin.py:115} INFO - [2022-12-13 23:23:21,948] {dagbag.py:320} ERROR - Failed to import: /home/igor/Documents/airflowalura/dags/dados_climaticos.py
Traceback (most recent call last):
  File "/home/igor/Documents/airflowalura/venv/lib/python3.9/site-packages/airflow/models/dagbag.py", line 317, in parse
    loader.exec_module(new_module)
  File "<frozen importlib._bootstrap_external>", line 850, in exec_module
  File "<frozen importlib._bootstrap>", line 228, in _call_with_frames_removed
  File "/home/igor/Documents/airflowalura/dags/dados_climaticos.py", line 40, in <module>
    task_2 = PythonOperator(
  File "/home/igor/Documents/airflowalura/venv/lib/python3.9/site-packages/airflow/models/baseoperator.py", line 390, in apply_defaults
    result = func(self, **kwargs, default_args=default_args)
  File "/home/igor/Documents/airflowalura/venv/lib/python3.9/site-packages/airflow/operators/python.py", line 156, in __init__
    super().__init__(**kwargs)
  File "/home/igor/Documents/airflowalura/venv/lib/python3.9/site-packages/airflow/models/baseoperator.py", line 390, in apply_defaults
    result = func(self, **kwargs, default_args=default_args)
  File "/home/igor/Documents/airflowalura/venv/lib/python3.9/site-packages/airflow/models/baseoperator.py", line 754, in __init__
    validate_key(task_id)
  File "/home/igor/Documents/airflowalura/venv/lib/python3.9/site-packages/airflow/utils/helpers.py", line 63, in validate_key
    raise AirflowException(
airflow.exceptions.AirflowException: The key 'extrai dados' has to be made of alphanumeric characters, dashes, dots and underscores exclusively
[2022-12-13 23:23:21,963] {processor.py:653} WARNING - No viable dags retrieved from /home/igor/Documents/airflowalura/dags/dados_climaticos.py
[2022-12-13 23:23:22,080] {processor.py:161} INFO - Processing /home/igor/Documents/airflowalura/dags/dados_climaticos.py took 4.271 seconds
[2022-12-13 23:23:58,589] {processor.py:153} INFO - Started process (PID=38533) to work on /home/igor/Documents/airflowalura/dags/dados_climaticos.py
[2022-12-13 23:23:58,592] {processor.py:641} INFO - Processing file /home/igor/Documents/airflowalura/dags/dados_climaticos.py for tasks to queue
[2022-12-13 23:23:58,608] {logging_mixin.py:115} INFO - [2022-12-13 23:23:58,605] {dagbag.py:507} INFO - Filling up the DagBag from /home/igor/Documents/airflowalura/dags/dados_climaticos.py
[2022-12-13 23:24:02,388] {logging_mixin.py:115} INFO - [2022-12-13 23:24:02,359] {dagbag.py:320} ERROR - Failed to import: /home/igor/Documents/airflowalura/dags/dados_climaticos.py
Traceback (most recent call last):
  File "/home/igor/Documents/airflowalura/venv/lib/python3.9/site-packages/airflow/models/dagbag.py", line 317, in parse
    loader.exec_module(new_module)
  File "<frozen importlib._bootstrap_external>", line 850, in exec_module
  File "<frozen importlib._bootstrap>", line 228, in _call_with_frames_removed
  File "/home/igor/Documents/airflowalura/dags/dados_climaticos.py", line 40, in <module>
    task_2 = PythonOperator(
  File "/home/igor/Documents/airflowalura/venv/lib/python3.9/site-packages/airflow/models/baseoperator.py", line 390, in apply_defaults
    result = func(self, **kwargs, default_args=default_args)
  File "/home/igor/Documents/airflowalura/venv/lib/python3.9/site-packages/airflow/operators/python.py", line 156, in __init__
    super().__init__(**kwargs)
  File "/home/igor/Documents/airflowalura/venv/lib/python3.9/site-packages/airflow/models/baseoperator.py", line 390, in apply_defaults
    result = func(self, **kwargs, default_args=default_args)
  File "/home/igor/Documents/airflowalura/venv/lib/python3.9/site-packages/airflow/models/baseoperator.py", line 754, in __init__
    validate_key(task_id)
  File "/home/igor/Documents/airflowalura/venv/lib/python3.9/site-packages/airflow/utils/helpers.py", line 63, in validate_key
    raise AirflowException(
airflow.exceptions.AirflowException: The key 'extrai dados' has to be made of alphanumeric characters, dashes, dots and underscores exclusively
[2022-12-13 23:24:02,391] {processor.py:653} WARNING - No viable dags retrieved from /home/igor/Documents/airflowalura/dags/dados_climaticos.py
[2022-12-13 23:24:02,562] {processor.py:161} INFO - Processing /home/igor/Documents/airflowalura/dags/dados_climaticos.py took 4.036 seconds
[2022-12-13 23:24:35,509] {processor.py:153} INFO - Started process (PID=38616) to work on /home/igor/Documents/airflowalura/dags/dados_climaticos.py
[2022-12-13 23:24:35,511] {processor.py:641} INFO - Processing file /home/igor/Documents/airflowalura/dags/dados_climaticos.py for tasks to queue
[2022-12-13 23:24:35,513] {logging_mixin.py:115} INFO - [2022-12-13 23:24:35,513] {dagbag.py:507} INFO - Filling up the DagBag from /home/igor/Documents/airflowalura/dags/dados_climaticos.py
[2022-12-13 23:24:39,244] {logging_mixin.py:115} INFO - [2022-12-13 23:24:39,228] {dagbag.py:320} ERROR - Failed to import: /home/igor/Documents/airflowalura/dags/dados_climaticos.py
Traceback (most recent call last):
  File "/home/igor/Documents/airflowalura/venv/lib/python3.9/site-packages/airflow/models/dagbag.py", line 317, in parse
    loader.exec_module(new_module)
  File "<frozen importlib._bootstrap_external>", line 850, in exec_module
  File "<frozen importlib._bootstrap>", line 228, in _call_with_frames_removed
  File "/home/igor/Documents/airflowalura/dags/dados_climaticos.py", line 40, in <module>
    task_2 = PythonOperator(
  File "/home/igor/Documents/airflowalura/venv/lib/python3.9/site-packages/airflow/models/baseoperator.py", line 390, in apply_defaults
    result = func(self, **kwargs, default_args=default_args)
  File "/home/igor/Documents/airflowalura/venv/lib/python3.9/site-packages/airflow/operators/python.py", line 156, in __init__
    super().__init__(**kwargs)
  File "/home/igor/Documents/airflowalura/venv/lib/python3.9/site-packages/airflow/models/baseoperator.py", line 390, in apply_defaults
    result = func(self, **kwargs, default_args=default_args)
  File "/home/igor/Documents/airflowalura/venv/lib/python3.9/site-packages/airflow/models/baseoperator.py", line 754, in __init__
    validate_key(task_id)
  File "/home/igor/Documents/airflowalura/venv/lib/python3.9/site-packages/airflow/utils/helpers.py", line 63, in validate_key
    raise AirflowException(
airflow.exceptions.AirflowException: The key 'extrai dados' has to be made of alphanumeric characters, dashes, dots and underscores exclusively
[2022-12-13 23:24:39,250] {processor.py:653} WARNING - No viable dags retrieved from /home/igor/Documents/airflowalura/dags/dados_climaticos.py
[2022-12-13 23:24:39,344] {processor.py:161} INFO - Processing /home/igor/Documents/airflowalura/dags/dados_climaticos.py took 3.880 seconds
[2022-12-13 23:25:12,217] {processor.py:153} INFO - Started process (PID=38714) to work on /home/igor/Documents/airflowalura/dags/dados_climaticos.py
[2022-12-13 23:25:12,229] {processor.py:641} INFO - Processing file /home/igor/Documents/airflowalura/dags/dados_climaticos.py for tasks to queue
[2022-12-13 23:25:12,230] {logging_mixin.py:115} INFO - [2022-12-13 23:25:12,230] {dagbag.py:507} INFO - Filling up the DagBag from /home/igor/Documents/airflowalura/dags/dados_climaticos.py
[2022-12-13 23:25:15,843] {logging_mixin.py:115} INFO - [2022-12-13 23:25:15,833] {dagbag.py:320} ERROR - Failed to import: /home/igor/Documents/airflowalura/dags/dados_climaticos.py
Traceback (most recent call last):
  File "/home/igor/Documents/airflowalura/venv/lib/python3.9/site-packages/airflow/models/dagbag.py", line 317, in parse
    loader.exec_module(new_module)
  File "<frozen importlib._bootstrap_external>", line 850, in exec_module
  File "<frozen importlib._bootstrap>", line 228, in _call_with_frames_removed
  File "/home/igor/Documents/airflowalura/dags/dados_climaticos.py", line 40, in <module>
    task_2 = PythonOperator(
  File "/home/igor/Documents/airflowalura/venv/lib/python3.9/site-packages/airflow/models/baseoperator.py", line 390, in apply_defaults
    result = func(self, **kwargs, default_args=default_args)
  File "/home/igor/Documents/airflowalura/venv/lib/python3.9/site-packages/airflow/operators/python.py", line 156, in __init__
    super().__init__(**kwargs)
  File "/home/igor/Documents/airflowalura/venv/lib/python3.9/site-packages/airflow/models/baseoperator.py", line 390, in apply_defaults
    result = func(self, **kwargs, default_args=default_args)
  File "/home/igor/Documents/airflowalura/venv/lib/python3.9/site-packages/airflow/models/baseoperator.py", line 754, in __init__
    validate_key(task_id)
  File "/home/igor/Documents/airflowalura/venv/lib/python3.9/site-packages/airflow/utils/helpers.py", line 63, in validate_key
    raise AirflowException(
airflow.exceptions.AirflowException: The key 'extrai dados' has to be made of alphanumeric characters, dashes, dots and underscores exclusively
[2022-12-13 23:25:15,851] {processor.py:653} WARNING - No viable dags retrieved from /home/igor/Documents/airflowalura/dags/dados_climaticos.py
[2022-12-13 23:25:15,934] {processor.py:161} INFO - Processing /home/igor/Documents/airflowalura/dags/dados_climaticos.py took 3.743 seconds
[2022-12-13 23:25:49,746] {processor.py:153} INFO - Started process (PID=38805) to work on /home/igor/Documents/airflowalura/dags/dados_climaticos.py
[2022-12-13 23:25:49,752] {processor.py:641} INFO - Processing file /home/igor/Documents/airflowalura/dags/dados_climaticos.py for tasks to queue
[2022-12-13 23:25:49,753] {logging_mixin.py:115} INFO - [2022-12-13 23:25:49,753] {dagbag.py:507} INFO - Filling up the DagBag from /home/igor/Documents/airflowalura/dags/dados_climaticos.py
[2022-12-13 23:25:52,805] {logging_mixin.py:115} INFO - [2022-12-13 23:25:52,800] {dagbag.py:320} ERROR - Failed to import: /home/igor/Documents/airflowalura/dags/dados_climaticos.py
Traceback (most recent call last):
  File "/home/igor/Documents/airflowalura/venv/lib/python3.9/site-packages/airflow/models/dagbag.py", line 317, in parse
    loader.exec_module(new_module)
  File "<frozen importlib._bootstrap_external>", line 850, in exec_module
  File "<frozen importlib._bootstrap>", line 228, in _call_with_frames_removed
  File "/home/igor/Documents/airflowalura/dags/dados_climaticos.py", line 40, in <module>
    task_2 = PythonOperator(
  File "/home/igor/Documents/airflowalura/venv/lib/python3.9/site-packages/airflow/models/baseoperator.py", line 390, in apply_defaults
    result = func(self, **kwargs, default_args=default_args)
  File "/home/igor/Documents/airflowalura/venv/lib/python3.9/site-packages/airflow/operators/python.py", line 156, in __init__
    super().__init__(**kwargs)
  File "/home/igor/Documents/airflowalura/venv/lib/python3.9/site-packages/airflow/models/baseoperator.py", line 390, in apply_defaults
    result = func(self, **kwargs, default_args=default_args)
  File "/home/igor/Documents/airflowalura/venv/lib/python3.9/site-packages/airflow/models/baseoperator.py", line 754, in __init__
    validate_key(task_id)
  File "/home/igor/Documents/airflowalura/venv/lib/python3.9/site-packages/airflow/utils/helpers.py", line 63, in validate_key
    raise AirflowException(
airflow.exceptions.AirflowException: The key 'extrai dados' has to be made of alphanumeric characters, dashes, dots and underscores exclusively
[2022-12-13 23:25:52,807] {processor.py:653} WARNING - No viable dags retrieved from /home/igor/Documents/airflowalura/dags/dados_climaticos.py
[2022-12-13 23:25:52,982] {processor.py:161} INFO - Processing /home/igor/Documents/airflowalura/dags/dados_climaticos.py took 3.268 seconds
[2022-12-13 23:26:26,046] {processor.py:153} INFO - Started process (PID=38900) to work on /home/igor/Documents/airflowalura/dags/dados_climaticos.py
[2022-12-13 23:26:26,051] {processor.py:641} INFO - Processing file /home/igor/Documents/airflowalura/dags/dados_climaticos.py for tasks to queue
[2022-12-13 23:26:26,053] {logging_mixin.py:115} INFO - [2022-12-13 23:26:26,053] {dagbag.py:507} INFO - Filling up the DagBag from /home/igor/Documents/airflowalura/dags/dados_climaticos.py
[2022-12-13 23:26:29,504] {logging_mixin.py:115} INFO - [2022-12-13 23:26:29,497] {dagbag.py:320} ERROR - Failed to import: /home/igor/Documents/airflowalura/dags/dados_climaticos.py
Traceback (most recent call last):
  File "/home/igor/Documents/airflowalura/venv/lib/python3.9/site-packages/airflow/models/dagbag.py", line 317, in parse
    loader.exec_module(new_module)
  File "<frozen importlib._bootstrap_external>", line 850, in exec_module
  File "<frozen importlib._bootstrap>", line 228, in _call_with_frames_removed
  File "/home/igor/Documents/airflowalura/dags/dados_climaticos.py", line 40, in <module>
    task_2 = PythonOperator(
  File "/home/igor/Documents/airflowalura/venv/lib/python3.9/site-packages/airflow/models/baseoperator.py", line 390, in apply_defaults
    result = func(self, **kwargs, default_args=default_args)
  File "/home/igor/Documents/airflowalura/venv/lib/python3.9/site-packages/airflow/operators/python.py", line 156, in __init__
    super().__init__(**kwargs)
  File "/home/igor/Documents/airflowalura/venv/lib/python3.9/site-packages/airflow/models/baseoperator.py", line 390, in apply_defaults
    result = func(self, **kwargs, default_args=default_args)
  File "/home/igor/Documents/airflowalura/venv/lib/python3.9/site-packages/airflow/models/baseoperator.py", line 754, in __init__
    validate_key(task_id)
  File "/home/igor/Documents/airflowalura/venv/lib/python3.9/site-packages/airflow/utils/helpers.py", line 63, in validate_key
    raise AirflowException(
airflow.exceptions.AirflowException: The key 'extrai dados' has to be made of alphanumeric characters, dashes, dots and underscores exclusively
[2022-12-13 23:26:29,506] {processor.py:653} WARNING - No viable dags retrieved from /home/igor/Documents/airflowalura/dags/dados_climaticos.py
[2022-12-13 23:26:29,606] {processor.py:161} INFO - Processing /home/igor/Documents/airflowalura/dags/dados_climaticos.py took 3.597 seconds
[2022-12-13 23:27:01,718] {processor.py:153} INFO - Started process (PID=38993) to work on /home/igor/Documents/airflowalura/dags/dados_climaticos.py
[2022-12-13 23:27:01,720] {processor.py:641} INFO - Processing file /home/igor/Documents/airflowalura/dags/dados_climaticos.py for tasks to queue
[2022-12-13 23:27:01,739] {logging_mixin.py:115} INFO - [2022-12-13 23:27:01,721] {dagbag.py:507} INFO - Filling up the DagBag from /home/igor/Documents/airflowalura/dags/dados_climaticos.py
[2022-12-13 23:27:04,955] {logging_mixin.py:115} INFO - [2022-12-13 23:27:04,931] {dagbag.py:320} ERROR - Failed to import: /home/igor/Documents/airflowalura/dags/dados_climaticos.py
Traceback (most recent call last):
  File "/home/igor/Documents/airflowalura/venv/lib/python3.9/site-packages/airflow/models/dagbag.py", line 317, in parse
    loader.exec_module(new_module)
  File "<frozen importlib._bootstrap_external>", line 850, in exec_module
  File "<frozen importlib._bootstrap>", line 228, in _call_with_frames_removed
  File "/home/igor/Documents/airflowalura/dags/dados_climaticos.py", line 40, in <module>
    task_2 = PythonOperator(
  File "/home/igor/Documents/airflowalura/venv/lib/python3.9/site-packages/airflow/models/baseoperator.py", line 390, in apply_defaults
    result = func(self, **kwargs, default_args=default_args)
  File "/home/igor/Documents/airflowalura/venv/lib/python3.9/site-packages/airflow/operators/python.py", line 156, in __init__
    super().__init__(**kwargs)
  File "/home/igor/Documents/airflowalura/venv/lib/python3.9/site-packages/airflow/models/baseoperator.py", line 390, in apply_defaults
    result = func(self, **kwargs, default_args=default_args)
  File "/home/igor/Documents/airflowalura/venv/lib/python3.9/site-packages/airflow/models/baseoperator.py", line 754, in __init__
    validate_key(task_id)
  File "/home/igor/Documents/airflowalura/venv/lib/python3.9/site-packages/airflow/utils/helpers.py", line 63, in validate_key
    raise AirflowException(
airflow.exceptions.AirflowException: The key 'extrai dados' has to be made of alphanumeric characters, dashes, dots and underscores exclusively
[2022-12-13 23:27:04,956] {processor.py:653} WARNING - No viable dags retrieved from /home/igor/Documents/airflowalura/dags/dados_climaticos.py
[2022-12-13 23:27:05,074] {processor.py:161} INFO - Processing /home/igor/Documents/airflowalura/dags/dados_climaticos.py took 3.390 seconds
[2022-12-13 23:27:42,466] {processor.py:153} INFO - Started process (PID=39100) to work on /home/igor/Documents/airflowalura/dags/dados_climaticos.py
[2022-12-13 23:27:42,476] {processor.py:641} INFO - Processing file /home/igor/Documents/airflowalura/dags/dados_climaticos.py for tasks to queue
[2022-12-13 23:27:42,478] {logging_mixin.py:115} INFO - [2022-12-13 23:27:42,478] {dagbag.py:507} INFO - Filling up the DagBag from /home/igor/Documents/airflowalura/dags/dados_climaticos.py
[2022-12-13 23:27:45,860] {logging_mixin.py:115} INFO - [2022-12-13 23:27:45,857] {dagbag.py:320} ERROR - Failed to import: /home/igor/Documents/airflowalura/dags/dados_climaticos.py
Traceback (most recent call last):
  File "/home/igor/Documents/airflowalura/venv/lib/python3.9/site-packages/airflow/models/dagbag.py", line 317, in parse
    loader.exec_module(new_module)
  File "<frozen importlib._bootstrap_external>", line 850, in exec_module
  File "<frozen importlib._bootstrap>", line 228, in _call_with_frames_removed
  File "/home/igor/Documents/airflowalura/dags/dados_climaticos.py", line 40, in <module>
    task_2 = PythonOperator(
  File "/home/igor/Documents/airflowalura/venv/lib/python3.9/site-packages/airflow/models/baseoperator.py", line 390, in apply_defaults
    result = func(self, **kwargs, default_args=default_args)
  File "/home/igor/Documents/airflowalura/venv/lib/python3.9/site-packages/airflow/operators/python.py", line 156, in __init__
    super().__init__(**kwargs)
  File "/home/igor/Documents/airflowalura/venv/lib/python3.9/site-packages/airflow/models/baseoperator.py", line 390, in apply_defaults
    result = func(self, **kwargs, default_args=default_args)
  File "/home/igor/Documents/airflowalura/venv/lib/python3.9/site-packages/airflow/models/baseoperator.py", line 754, in __init__
    validate_key(task_id)
  File "/home/igor/Documents/airflowalura/venv/lib/python3.9/site-packages/airflow/utils/helpers.py", line 63, in validate_key
    raise AirflowException(
airflow.exceptions.AirflowException: The key 'extrai dados' has to be made of alphanumeric characters, dashes, dots and underscores exclusively
[2022-12-13 23:27:45,860] {processor.py:653} WARNING - No viable dags retrieved from /home/igor/Documents/airflowalura/dags/dados_climaticos.py
[2022-12-13 23:27:45,962] {processor.py:161} INFO - Processing /home/igor/Documents/airflowalura/dags/dados_climaticos.py took 3.544 seconds
